Workbook

Sheet Summary 
B2: Analysis and Summary: J.B. Hunt
B4: $ in thousands
B5: Key Metrics | C5: 2025 | D5: 2026 | E5: 2027 | F5: 2028 | J5: Date: | K5: 46303
B6: Revenue | C6: =Projections!C5 -> 11999096 | D6: =Projections!D5 -> 12719042 | E6: =Projections!E5 -> 13227803 | F6: =Projections!F5 -> 13756916
B7: EBITDA | C7: =Projections!C8 -> 1579854 | D7: =Projections!D8 -> 1717325.3 | E7: =Projections!E8 -> 1756377.2 | F7: =Projections!F8 -> 1826632.3
B8: Gross Debt/EBITDA | C8: =Projections!C15 -> 0.92843832 | D8: =Projections!D15 -> 0.85994192 | E8: =Projections!E15 -> 0.84082167 | F8: =Projections!F15 -> 0.80848237
B9: Interest Coverage | C9: =Projections!C16 -> 11.502659 | D9: =Projections!D16 -> 12.684202 | E9: =Projections!E16 -> 12.797438 | F9: =Projections!F16 -> 13.309336
B10: Free Cash Flow | C10: =Projections!C11 -> 947585 | D10: =Projections!D11 -> 534741.99 | E10: =Projections!E11 -> 536077.13 | F10: =Projections!F11 -> 559785.42
B11: DSCR | C11: ='Severe Downside Case'!C13 -> 1.1371071 | D11: ='Severe Downside Case'!D13 -> 0.71181901 | E11: ='Severe Downside Case'!E13 -> 5.6205355 | F11: ='Severe Downside Case'!F13 -> 5.5130648 | G11: *2027 and 2028 Exclude Term Loan maturity
B12: Liquidity | C12: =Liquidity!F12 -> 990484 | G12: * DSCR are from severe Downside case, excluding 2025
B15: Historical Metrics | C15: 2023 | D15: =C15+1 -> 2024 | E15: =D15+1 -> 2025
B16: Current Ratio | C16: =Liquidity!D17 -> 1.3502182 | D16: =Liquidity!E17 -> 1.0553878 | E16: =Liquidity!F17 -> 0.82889183
B17: Cash + revolver liquidity | C17: =Liquidity!D18 -> 923344 | D17: =Liquidity!E18 -> 766983 | E17: =Liquidity!F18 -> 990484
B18: Liquidity/Current Liabilities | C18: =Liquidity!D19 -> 0.63569294 | D18: =Liquidity!E19 -> 0.45707075 | E18: =Liquidity!F19 -> 0.51178732
B19: Buybacks and Payouts | E19: =-'Historical Financials'!F81-'Historical Financials'!F83 -> 1094340
B21: Strengths:
B22: $ 1B Revolving line of credit, with 973.2M undrawn as of 2025
B23: Even with severe downside case, leverage and interest coverage do not fluctuate much, with a peak of leverage at 1.1 and a low for interest coverage of 9x.
B24: first half revenue 2026 was up 12% vs. prior year
B26: Concerns:
B27: total of 1.476B of debt outstanding, 700M due in 2026. 2026 DSCR of 0.7 shows repayment depends on refinancing, backed by up to $700M of committed term loans.
B28: Buybacks and dividends are high and may threaten cash
B29: Revenue decreased YoY from 2023 to 2024 of -5.79% and from 2024 to 2025 of -.73%

Sheet Historical Financials
B2: J.B Hunt Historical Financials
C4: $ In Thousands
B5: x | C5: Income Statement | D5: 2023 | E5: =D5+1 -> 2024 | F5: =E5+1 -> 2025
C6: Operating Revenues | D6: 12829665 | E6: 12087204 | F6: 11999096
C7: Operating Expenses | D7: -11836469 | E7: -11255979 | F7: -11134027
C8: Operating Income | D8: =D6+D7 -> 993196 | E8: =E6+E7 -> 831225 | F8: =F6+F7 -> 865069
C9: Interest Income | D9: 7624 | E9: 7311 | F9: 4249
C10: Interest Expense | D10: -65933 | E10: -79020 | F10: -75206
C11: EBT | D11: =D8+D9+D10 -> 934887 | E11: =E8+E9+E10 -> 759516 | F11: =F8+F9+F10 -> 794112
C12: Income Taxes | D12: -206600 | E12: -188630 | F12: -195830
C13: Net Income | D13: =D11+D12 -> 728287 | E13: =E11+E12 -> 570886 | F13: =F11+F12 -> 598282
B17: x | C17: Balance Sheet | D17: 2023 | E17: =D17+1 -> 2024 | F17: =E17+1 -> 2025
C18: Cash and Equivalents | D18: =D88 -> 53344 | E18: =E88 -> 46983 | F18: =F88 -> 17284
C19: Trade AR, Net | D19: 1334912 | E19: 1224166 | F19: 1160371
C20: Other Receivables | D20: 231248 | E20: 257774 | F20: 199767
C21: Inventories | D21: 42186 | E21: 41662 | F21: 42209
C22: Prepaid Expenses | D22: 299502 | E22: 200398 | F22: 184559
C23: Total Current Assets | D23: =SUM(D18:D22) -> 1961192 | E23: =SUM(E18:E22) -> 1770983 | F23: =SUM(F18:F22) -> 1604190
C24: Gross PP&E | D24: 8767872 | E24: 9148928 | F24: 9348370
C25: Accumulated Dep. | D25: -2993959 | E25: -3419129 | F25: -3810269
C26: Net PP&E | D26: =D24+D25 -> 5773913 | E26: =E24+E25 -> 5729799 | F26: =F24+F25 -> 5538101
C27: Goodwill | D27: 134057 | E27: 134057 | F27: 134057
C28: Other Intangible Assets | D28: 133896 | E28: 96922 | F28: 76300
C29: Other Assets | D29: 585090 | E29: 580509 | F29: 574507
C30: Total Assets | D30: =D23+SUM(D26:D29) -> 8588148 | E30: =E23+SUM(E26:E29) -> 8312270 | F30: =F23+SUM(F26:F29) -> 7927155
B33: x | C33: Liabilities and SHE: | D33: 2023 | E33: =D33+1 -> 2024 | F33: =E33+1 -> 2025
C34: Current Long-term Debt | D34: 249961 | E34: 500000 | F34: 699859
C35: Trade Accounts Payable | D35: 737364 | E35: 645925 | F35: 655604
C36: Claims Accruals | D36: 220357 | E36: 257121 | F36: 310339
C37: Accrued payroll and payroll taxes | D37: 94563 | E37: 122477 | F37: 110388
C38: other accrued expenses | D38: 150255 | E38: 152517 | F38: 159153
C39: long-term debt | D39: 1326107 | E39: 977702 | F39: 766938
C40: long-term claims accruals | D40: 326920 | E40: 368704 | F40: 444479
C41: other long-term liabilities | D41: 392766 | E41: 377070 | F41: 307005
C42: Deferred income taxes | D42: 986097 | E42: 896249 | F42: 908305
C43: Total Liabilities | D43: =SUM(D34:D42) -> 4484390 | E43: =SUM(E34:E42) -> 4297765 | F43: =SUM(F34:F42) -> 4362070
C45: Common Stock | D45: 1671 | E45: 1671 | F45: 1671
C46: APIC | D46: 549132 | E46: 583945 | F46: 627280
C47: Retained Earnings | D47: 6978119 | E47: 7373462 | F47: 7800696
C48: Treasury Stock | D48: -3425164 | E48: -3944573 | F48: -4864562
...

Sheet Credit Ratios
B2: CREDIT RATIOS
C4: Historical Years | D4: 2023 | E4: =D4+1 -> 2024 | F4: =E4+1 -> 2025
C6: Revenue Growth | D6: N/A | E6: =('Historical Financials'!E6-'Historical Financials'!D6)/'Historical Financials'!D6 -> -0.057870646 | F6: =('Historical Financials'!F6-'Historical Financials'!E6)/'Historical Financials'!E6 -> -0.0072893615
C8: EBITDA Margin | D8: =('Historical Financials'!D8+'Historical Financials'!D58)/'Historical Financials'!D6 -> 0.13493338 | E8: =('Historical Financials'!E8+'Historical Financials'!E58)/'Historical Financials'!E6 -> 0.13173981 | F8: =('Historical Financials'!F8+'Historical Financials'!F58)/'Historical Financials'!F6 -> 0.13166442
C10: EBIT Margin | D10: ='Historical Financials'!D8/'Historical Financials'!D6 -> 0.077414024 | E10: ='Historical Financials'!E8/'Historical Financials'!E6 -> 0.068769006 | F10: ='Historical Financials'!F8/'Historical Financials'!F6 -> 0.072094514
C14: Leverage
C16: Gross Debt/EBITDA | D16: =('Historical Financials'!D34+'Historical Financials'!D39)/('Historical Financials'!D8+'Historical Financials'!D58) -> 0.91041677 | E16: =('Historical Financials'!E34+'Historical Financials'!E39)/('Historical Financials'!E8+'Historical Financials'!E58) -> 0.92799143 | F16: =('Historical Financials'!F34+'Historical Financials'!F39)/('Historical Financials'!F8+'Historical Financials'!F58) -> 0.92843832
C17: Net Debt/EBITDA | D17: =('Historical Financials'!D34+'Historical Financials'!D39-'Historical Financials'!D18)/('Historical Financials'!D8+'Historical Financials'!D58) -> 0.87960258 | E17: =('Historical Financials'!E34+'Historical Financials'!E39-'Historical Financials'!E18)/('Historical Financials'!E8+'Historical Financials'!E58) -> 0.89848628 | F17: =('Historical Financials'!F34+'Historical Financials'!F39-'Historical Financials'!F18)/('Historical Financials'!F8+'Historical Financials'!F58) -> 0.91749807
C19: Interest Coverage | D19: ='Historical Financials'!D8/-'Historical Financials'!D10 -> 15.063716 | E19: ='Historical Financials'!E8/-'Historical Financials'!E10 -> 10.519172 | F19: ='Historical Financials'!F8/-'Historical Financials'!F10 -> 11.502659
B20: *FCF as CFO-CapEx | C20: Free Cash Flow | D20: ='Historical Financials'!D69+'Historical Financials'!D71 -> -117813 | E20: ='Historical Financials'!E69+'Historical Financials'!E71 -> 617783 | F20: ='Historical Financials'!F69+'Historical Financials'!F71 -> 947585
C21: FCF/Interest | D21: =D20/-'Historical Financials'!D10 -> -1.7868594 | E21: =E20/-'Historical Financials'!E10 -> 7.8180587 | F21: =F20/-'Historical Financials'!F10 -> 12.599859

Sheet Liquidity
B2: Liquidity Analysis
C4: Metric | D4: 2023 | E4: =D4+1 -> 2024 | F4: =E4+1 -> 2025
C5: Cash & Equivalents | D5: ='Historical Financials'!D88 -> 53344 | E5: ='Historical Financials'!E88 -> 46983 | F5: ='Historical Financials'!F88 -> 17284
C6: Current Assets | D6: ='Historical Financials'!D23 -> 1961192 | E6: ='Historical Financials'!E23 -> 1770983 | F6: ='Historical Financials'!F23 -> 1604190
C7: Current Liabilities | D7: =SUM('Historical Financials'!D34:D38) -> 1452500 | E7: =SUM('Historical Financials'!E34:E38) -> 1678040 | F7: =SUM('Historical Financials'!F34:F38) -> 1935343
C8: Current portion of debt | D8: ='Historical Financials'!D34 -> 249961 | E8: ='Historical Financials'!E34 -> 500000 | F8: ='Historical Financials'!F34 -> 699859
C9: Operating Cash Flow | D9: ='Historical Financials'!D69 -> 1744618 | E9: ='Historical Financials'!E69 -> 1483156 | F9: ='Historical Financials'!F69 -> 1678272
C10: FCF | D10: ='Credit Ratios'!D20 -> -117813 | E10: ='Credit Ratios'!E20 -> 617783 | F10: ='Credit Ratios'!F20 -> 947585
C11: Undrawn Revolver | D11: 870000 | E11: 720000 | F11: 973200
C12: Total Available Liquidity | D12: =D11+D5 -> 923344 | E12: =E11+E5 -> 766983 | F12: =F11+F5 -> 990484
C16: Ratios
C17: Current Ratio | D17: =D6/D7 -> 1.3502182 | E17: =E6/E7 -> 1.0553878 | F17: =F6/F7 -> 0.82889183
C18: Cash + revolver liquidity | D18: =D12 -> 923344 | E18: =E12 -> 766983 | F18: =F12 -> 990484
C19: Liquidity/Current Liabilities | D19: =D12/D7 -> 0.63569294 | E19: =E12/E7 -> 0.45707075 | F19: =F12/F7 -> 0.51178732

Sheet Debt Schedule
B2: Debt Schedule
B4: $ in thousands | C4: 2025
C5: Instrument | D5: Revolver | E5: Senior Notes | F5: Senior Notes
C6: Amount | D6: 26800 | E6: 700000 | F6: 750000
C7: Rate | D7: 0.0462 | E7: 0.03875 | F7: 0.049
C8: Maturity | D8: 47788 | E8: 46082 | F8: 47543
C10: Total 2025 Debt | D10: =D6+E6+F6 -> 1476800 | E10: Unamortized debt issuance | F10: =D10-('Historical Financials'!F34+'Historical Financials'!F39) -> 10003
C12: 2024
C13: Instrument | D13: Revolver | E13: Senior Notes | F13: Term Loan
C14: Amount | D14: 280000 | E14: 700000 | F14: 500000
C15: Rate | D15: 0.0548 | E15: 0.03875 | F15: 0.0548
C16: Maturity | D16: 46631 | E16: 46082 | F16: 45901
C18: Total 2024 Debt | D18: =D14+E14+F14 -> 1480000 | E18: Unamortized debt issuance | F18: =D18-('Historical Financials'!E34+'Historical Financials'!E39) -> 2298
C20: 2023
C21: Instrument | D21: Revolver | E21: Senior Notes | F21: Senior Notes | G21: Term Loan
C22: Amount | D22: 130000 | E22: 250000 | F22: 700000 | G22: 500000
C23: Rate | D23: 0.0644 | E23: 0.0385 | F23: 0.03875 | G23: 0.0644
C24: Maturity | D24: 46631 | E24: 45352 | F24: 46082 | G24: 45901
C26: Total 2023 Debt | D26: =SUM(D22:G22) -> 1580000 | E26: Unamoritzed debt issuance | F26: =D26-('Historical Financials'!D34+'Historical Financials'!D39) -> 3932
C29: Future Debt Maturity
C30: 2026 | D30: =E6 -> 700000
C31: 2027 | D31: 0
C32: 2028 | D32: 0
C33: 2029 | D33: 0
C34: 2030 | D34: =D6+F6 -> 776800
C35: Total | D35: =SUM(D30:D34) -> 1476800

Sheet Projections
B2: Projections
A4: x | B4: $ in thousands | C4: 2025 | D4: 2026 | E4: 2027 | F4: 2028
B5: Revenue | C5: ='Historical Financials'!F6 -> 11999096 | D5: =C5*(1+D18) -> 12719042 | E5: =D5*(1+E18) -> 13227803 | F5: =E5*(1+F18) -> 13756916
B6: Operating Income | C6: ='Historical Financials'!F8 -> 865069 | D6: =D5*D19 -> 953928.13 | E6: =E5*E19 -> 962444.15 | F6: =F5*F19 -> 1000941.9
B7: D&A Projections | C7: ='Historical Financials'!F58 -> 714785 | D7: =D5*AVERAGE('Historical Financials'!$D$93:$F$93) -> 763397.15 | E7: =E5*AVERAGE('Historical Financials'!$D$93:$F$93) -> 793933.04 | F7: =F5*AVERAGE('Historical Financials'!$D$93:$F$93) -> 825690.36
B8: EBITDA Projections | C8: =C6+C7 -> 1579854 | D8: =D6+D7 -> 1717325.3 | E8: =E6+E7 -> 1756377.2 | F8: =F6+F7 -> 1826632.3
B9: CAPEX Projections | C9: ='Historical Financials'!F71 -> -730687 | D9: =-D5*D22 -> -890332.92 | E9: =-E5*E22 -> -925946.24 | F9: =-F5*F22 -> -962984.09
B10: Interest Expense | C10: ='Historical Financials'!$F$10 -> -75206 | D10: ='Historical Financials'!$F$10 -> -75206 | E10: ='Historical Financials'!$F$10 -> -75206 | F10: ='Historical Financials'!$F$10 -> -75206
B11: Free Cash Flow | C11: =Liquidity!F10 -> 947585 | D11: =ABS(D8+D9+D10+D12) -> 534741.99 | E11: =ABS(E8+E9+E10+E12) -> 536077.13 | F11: =ABS(F8+F9+F10+F12) -> 559785.42
B12: Taxes | C12: =-(C6+C10)*C23 -> -194782.19 | D12: =-(D6+D10)*D23 -> -217044.37 | E12: =-(E6+E10)*E23 -> -219147.82 | F12: =-(F6+F10)*F23 -> -228656.77
A14: x | B14: Leverage Check
B15: Gross Debt/EBITDA | C15: ='Credit Ratios'!F16 -> 0.92843832 | D15: ='Debt Schedule'!$D$10/Projections!D8 -> 0.85994192 | E15: ='Debt Schedule'!$D$10/Projections!E8 -> 0.84082167 | F15: ='Debt Schedule'!$D$10/Projections!F8 -> 0.80848237
B16: Interest Coverage | C16: ='Credit Ratios'!F19 -> 11.502659 | D16: =-D6/D10 -> 12.684202 | E16: =-E6/E10 -> 12.797438 | F16: =-F6/F10 -> 13.309336
B18: Revenue Growth % | C18: ='Credit Ratios'!F6 -> -0.0072893615 | D18: =C37 -> 0.06 | E18: =C41 -> 0.04 | F18: =C42 -> 0.04
B19: Operating Income Margin % | C19: ='Historical Financials'!F8/'Historical Financials'!F6 -> 0.072094514 | D19: 0.075 | E19: =AVERAGE($C$43:$C$45) -> 0.072759182 | F19: =AVERAGE($C$43:$C$45) -> 0.072759182
B20: D&A as a % of revenue | C20: ='Historical Financials'!F93 -> 0.059569904 | D20: =AVERAGE('Historical Financials'!$D$93:$F$93) -> 0.060020021 | E20: =AVERAGE('Historical Financials'!$D$93:$F$93) -> 0.060020021 | F20: =AVERAGE('Historical Financials'!$D$93:$F$93) -> 0.060020021
B21: EBITDA % of Revenue | C21: =C8/C5 -> 0.13166442 | D21: =D8/D5 -> 0.13502002 | E21: =E8/E5 -> 0.1327792 | F21: =F8/F5 -> 0.1327792
B22: CAPEX as a % of Revenue | C22: ='Historical Financials'!F94 -> 0.060895171 | D22: 0.07 | E22: 0.07 | F22: 0.07
A23: x | B23: Tax Rate | C23: =-'Historical Financials'!F12/'Historical Financials'!F11 -> 0.24660249 | D23: =24.7% -> 0.247 | E23: =24.7% -> 0.247 | F23: =24.7% -> 0.247
B31: Revenue growth % proof | D31: Assumptions
B32: Label | C32: Numbers | D32: Operating Margin | E32: =E34/E33 -> 0.071201948
B33: 2025 full-year revenue | C33: ='Historical Financials'!F6 -> 11999096 | D33: 2026 first half | E33: =C36 -> 6551787
B34: 2025 First half | C34: =5849573 -> 5849573 | D34: 2026 OP Inc. | E34: 466500
B35: 2025 Second Half | C35: =C33-C34 -> 6149523 | D35: Operating Margin | E35: =E37/E36 -> 0.064270332
B36: 2026 first half | C36: =6551787 -> 6551787 | D36: First half 2025 | E36: =C34 -> 5849573
B37: Assumed 2026 Growth | C37: 0.06 | D37: 2025 OP Inc | E37: =375954 -> 375954
B38: Assumed 2026 Full Year | C38: =C33*(1+C37) -> 12719042
B39: 2026 Second Half Required | C39: =C38-C36 -> 6167254.8
B40: 1st Half 2026 Growth % | C40: =(C36/C34)-1 -> 0.12004534
B41: Revenue Growth estimate 2027 | C41: 0.04
B42: Revenue Growth Estimate 2028 | C42: 0.04
B43: 2025 Operating Income % | C43: =C19 -> 0.072094514
B44: 2024 Operating Income % | C44: ='Historical Financials'!E8/'Historical Financials'!E6 -> 0.068769006
B45: 2023 Operating Income % | C45: ='Historical Financials'!D8/'Historical Financials'!D6 -> 0.077414024

Sheet Severe Downside Case
B2: Severe Downside Case
A4: x | B4: $ in thousands | C4: 2025 | D4: 2026 | E4: 2027 | F4: 2028
B5: Revenue | C5: ='Historical Financials'!F6 -> 11999096 | D5: =C5*(1+D19) -> 12479060 | E5: =D5*(1+E19) -> 11480735 | F5: =E5*(1+F19) -> 11251120
B6: Operating Income | C6: ='Historical Financials'!F8 -> 865069 | D6: =D5*D20 -> 873534.19 | E6: =E5*E20 -> 688844.1 | F6: =F5*F20 -> 675067.22
B7: D&A Projections | C7: ='Historical Financials'!F58 -> 714785 | D7: =D5*AVERAGE('Historical Financials'!$D$93:$F$93) -> 748993.43 | E7: =E5*AVERAGE('Historical Financials'!$D$93:$F$93) -> 689073.96 | F7: =F5*AVERAGE('Historical Financials'!$D$93:$F$93) -> 675292.48
B8: EBITDA Projections | C8: =C6+C7 -> 1579854 | D8: =D6+D7 -> 1622527.6 | E8: =E6+E7 -> 1377918.1 | F8: =F6+F7 -> 1350359.7
B9: CAPEX Projections | C9: ='Historical Financials'!F71 -> -730687 | D9: =-D5*D23 -> -873534.19 | E9: =-E5*E23 -> -803651.45 | F9: =-F5*F23 -> -787578.42
B10: Interest Expense | C10: ='Historical Financials'!$F$10 -> -75206 | D10: ='Historical Financials'!$F$10 -> -75206 | E10: ='Historical Financials'!$F$10 -> -75206 | F10: ='Historical Financials'!$F$10 -> -75206
B11: Free Cash Flow | C11: =Liquidity!F10 -> 947585 | D11: =ABS(D8+D9+D10+D12) -> 476600.37 | E11: =ABS(E8+E9+E10+E12) -> 347492 | F11: =ABS(F8+F9+F10+F12) -> 339409.55
B12: Taxes | C12: =-(C6+C10)*C24 -> -195096.16 | D12: =-(D6+D10)*D24 -> -197187.06 | E12: =-(E6+E10)*E24 -> -151568.61 | F12: =-(F6+F10)*F24 -> -148165.72
B13: DSCR | C13: =(C8+C9+C12)/('Debt Schedule'!F14-'Severe Downside Case'!C10) -> 1.1371071 | D13: =(D8+D9+D12)/('Debt Schedule'!D30-'Severe Downside Case'!D10) -> 0.71181901 | E13: =(E8+E9+E12)/('Debt Schedule'!E30-'Severe Downside Case'!E10) -> 5.6205355 | F13: =(F8+F9+F12)/('Debt Schedule'!F30-'Severe Downside Case'!F10) -> 5.5130648
A15: x | B15: Leverage Check
B16: Gross Debt/EBITDA | C16: ='Credit Ratios'!F16 -> 0.92843832 | D16: ='Debt Schedule'!$D$10/'Severe Downside Case'!D8 -> 0.91018481 | E16: ='Debt Schedule'!$D$10/'Severe Downside Case'!E8 -> 1.0717618 | F16: ='Debt Schedule'!$D$10/'Severe Downside Case'!F8 -> 1.0936345
B17: Interest Coverage | C17: ='Credit Ratios'!F19 -> 11.502659 | D17: =-D6/D10 -> 11.615219 | E17: =-E6/E10 -> 9.1594301 | F17: =-F6/F10 -> 8.9762415
B19: Revenue Growth % | C19: ='Credit Ratios'!F6 -> -0.0072893615 | D19: 0.04 | E19: -0.08 | F19: -0.02 | G19: * Revenue growth and Operating Income margin are assumptions
B20: Operating Income Margin % | C20: ='Historical Financials'!F8/'Historical Financials'!F6 -> 0.072094514 | D20: 0.07 | E20: =6% -> 0.06 | F20: =6% -> 0.06 | G20: * Downside Case only
B21: D&A as a % of revenue | C21: ='Historical Financials'!F93 -> 0.059569904 | D21: =AVERAGE('Historical Financials'!$D$93:$F$93) -> 0.060020021 | E21: =AVERAGE('Historical Financials'!$D$93:$F$93) -> 0.060020021 | F21: =AVERAGE('Historical Financials'!$D$93:$F$93) -> 0.060020021
B22: EBITDA % of Revenue | C22: =C8/C5 -> 0.13166442 | D22: =D8/D5 -> 0.13002002 | E22: =E8/E5 -> 0.12002002 | F22: =F8/F5 -> 0.12002002
B23: CAPEX as a % of Revenue | C23: ='Historical Financials'!F94 -> 0.060895171 | D23: 0.07 | E23: 0.07 | F23: 0.07
A24: x | B24: Tax Rate | C24: =24.7% -> 0.247 | D24: =24.7% -> 0.247 | E24: =24.7% -> 0.247 | F24: =24.7% -> 0.247
